Workbook

Sheet Negocios
A2: Registro de negocios
A3: Lotes de 5 · Prioridad por puntuación · Checklist válida por etapa
A4: Registros | B4: =COUNTA(A7:A206) -> 60 | D4: Investigados | E4: =COUNTIFS(AO7:AO206,"Sí",A7:A206,"<>") -> 60 | G4: Seleccionados | H4: =COUNTIFS(AC7:AC206,"Seleccionado",A7:A206,"<>") -> 6 | J4: Terminados | K4: =COUNTIFS(AU7:AU206,"Sí",A7:A206,"<>") -> 1
A6: ID | B6: Campaña | C6: Lote | D6: Negocio | E6: Categoría | F6: Dirección | G6: Municipio | H6: Zona | I6: Actividad | J6: Confianza | K6: Presencia web | L6: URL web | M6: Carta digital | N6: Reservas online | O6: Pedidos online | P6: Venta productos | Q6: Fidelización | R6: Grupos eventos | S6: App externa | T6: Terraza | U6: Herramientas y enlaces | V6: Bien resuelto | W6: Fricción observada | X6: Oportunidades preliminares | Y6: Encaje innovador | Z6: Fuentes URL | AA6: Fecha revisión | AB6: Expediente | AC6: Decisión selección | AD6: Motivo selección o bloqueo | AE6: Estado operativo | AF6: Necesidad 1-10 | AG6: Valor añadido 1-10 | AH6: Información 1-10 | AI6: Mantenibilidad 1-10 | AJ6: Contacto 1-10 | AK6: Motivo puntuación | AL6: Puntuación 1-10 | AM6: Impacto post 1-10 | AN6: Motivo impacto post | AO6: 1 Investigación | AP6: 2 Webscraper | AQ6: 3 Innovador | AR6: 4 Demo | AS6: 5 Comercial | AT6: 6 Valoración | AU6: 7 Mensajero
A7: indh001 | B7: indautxu-hosteleria-001 | C7: lote-001 | D7: Asador Indusi | E7: Restaurante | F7: García Rivero, 7 | G7: Bilbao | H7: Dentro | I7: Activa con evidencia | J7: Alta | K7: Propia | L7: https://www.asadorindusi.com/ | M7: No localizado | N7: No confirmado | O7: No confirmado | P7: No aplica | Q7: No localizado | R7: No localizado | S7: No aplica | T7: Sin información | U7: Web propia asadorindusi.com; reserva declarada WhatsApp/email | V7: Identidad, contacto y propuesta asador claros en web oficial. | W7: Sin carta/precios online; reserva no autogestionada. | X7: Formulario reserva web + carta mínima (rol 4: volumen reservas). | Y7: Posible | Z7: https://www.asadorindusi.com/ | https://bilbaoclick.com/asador-indusi-cocina-autentica-vasca-en_centro-bilbao/ | AA7: 46292 | AB7: expedientes/0001_Indusi | AC7: Pendiente | AE7: Disponible | AF7: 5 | AG7: 5 | AH7: 7 | AI7: 7 | AJ7: 8 | AK7: Identidad sólida; fricción carta/reserva digital parcial; contacto profesional claro. | AL7: =IF(OR(A7="",COUNT(AF7:AJ7)<5),"",ROUND(SUMPRODUCT(AF7:AJ7,Guia!$B$7:$F$7),1)) -> 6 | AO7: Sí | AP7: No | AQ7: No | AR7: No | AS7: No | AT7: No | AU7: No
A8: indh002 | B8: indautxu-hosteleria-001 | C8: lote-001 | D8: Café Bahía | E8: Bar | F8: Manuel Allende, 12 | G8: Bilbao | H8: Dentro | I8: Activa con evidencia | J8: Alta | K8: Propia | L8: https://cafebahiabilbao.com/ | M8: No localizado | N8: No aplica | O8: No localizado | P8: No aplica | Q8: No localizado | R8: No localizado | S8: No aplica | T8: Sin información | U8: Web propia cafebahiabilbao.com | V8: Marca y propuesta (vermut/tardeo) bien comunicadas. | W8: Oferta de barra no digitalizada. | X8: Carta mínima u oferta tarde actualizable (rol 4: redes actuales). | Y8: Posible | Z8: https://cafebahiabilbao.com/ | AA8: 46292 | AB8: expedientes/0002_Bahia | AC8: Pendiente | AE8: Disponible | AF8: 6 | AG8: 5 | AH8: 6 | AI8: 8 | AJ8: 7 | AK8: Web clara pero poca información operativa; barra típica sin reserva. | AL8: =IF(OR(A8="",COUNT(AF8:AJ8)<5),"",ROUND(SUMPRODUCT(AF8:AJ8,Guia!$B$7:$F$7),1)) -> 6.2 | AO8: Sí | AP8: No | AQ8: No | AR8: No | AS8: No | AT8: No | AU8: No
A9: indh003 | B9: indautxu-hosteleria-001 | C9: lote-001 | D9: Bar Alondegui | E9: Bar | F9: Fernández del Campo, 35 | G9: Bilbao | H9: Dentro | I9: Activa con evidencia | J9: Alta | K9: Propia | L9: https://alondegui.com/ | M9: No localizado | N9: No aplica | O9: No localizado | P9: No aplica | Q9: No localizado | R9: No localizado | S9: No aplica | T9: Sí | U9: alondegui.com; Google Analytics (cookies); Instagram mencionado | V9: Horario, terraza y contacto email en nota legal. | W9: Barra sin precios online; redes sin URL en home. | X9: — | Y9: Posible | Z9: https://alondegui.com/ | https://alondegui.com/nuestra-barra-pintxos-raciones/ | AA9: 46292 | AB9: expedientes/0003_Alondegui | AC9: Pendiente | AE9: Disponible | AF9: 6 | AG9: 5 | AH9: 6 | AI9: 7 | AJ9: 7 | AK9: Presencia web estándar; oportunidad incremental no prioritaria aquí. | AL9: =IF(OR(A9="",COUNT(AF9:AJ9)<5),"",ROUND(SUMPRODUCT(AF9:AJ9,Guia!$B$7:$F$7),1)) -> 6 | AO9: Sí | AP9: No | AQ9: No | AR9: No | AS9: No | AT9: No | AU9: No
A10: indh004 | B10: indautxu-hosteleria-001 | C10: lote-001 | D10: Indautxu Batzokia | E10: Restaurante | F10: Indautxu Kalea, 7 | G10: Bilbao | H10: Dentro | I10: Activa con evidencia | J10: Alta | K10: Propia | L10: https://indautxubatzokia.com/ | M10: Sí | N10: No confirmado | O10: No localizado | P10: No aplica | Q10: No localizado | R10: No confirmado | S10: No aplica | T10: Sin información | U10: indautxubatzokia.com/la-carta; formulario solicitud reserva | V10: Carta amplia con precios online; teléfonos publicados. | W10: Reserva no instantánea; carta muy extensa (móvil no medido). | X10: — | Y10: No evidente | Z10: https://indautxubatzokia.com/ | https://indautxubatzokia.com/la-carta | AA10: 46292 | AB10: expedientes/0004_Batzokia | AC10: Pendiente | AE10: Disponible | AF10: 4 | AG10: 4 | AH10: 8 | AI10: 6 | AJ10: 8 | AK10: Alta cobertura digital; poca necesidad incremental visible en esta pasada. | AL10: =IF(OR(A10="",COUNT(AF10:AJ10)<5),"",ROUND(SUMPRODUCT(AF10:AJ10,Guia!$B$7:$F$7),1)) -> 5.4 | AO10: Sí | AP10: No | AQ10: No | AR10: No | AS10: No | AT10: No | AU10: No
A11: indh005 | B11: indautxu-hosteleria-001 | C11: lote-001 | D11: Bodega Indautxu | E11: Bar | F11: Gregorio de la Revilla, 18 | G11: Bilbao | H11: Dentro | I11: Activa con evidencia | J11: Media | K11: Solo terceros | M11: No localizado | N11: No localizado | O11: No localizado | P11: No aplica | Q11: No localizado | R11: No localizado | S11: No aplica | T11: Sí | U11: bilbaodendak.eus/comercios/bodega-indautxu; bilbaoalacarta.com | V11: Reputación offline documentada; teléfono/email en ficha municipal. | W11: Sin web/carta propia; descubrimiento vía terceros. | X11: Web mínima propia + premios/especialidades (rol 4: Google Business). | Y11: Claro | Z11: https://www.bilbaodendak.eus/comercios/bodega-indautxu/ | https://bilbaoalacarta.com/restaurante-bilbao/indatxu/ | AA11: 46293 | AB11: expedientes/0005_Bodega | AC11: Descartado | AD11: Operativa muy tradicional; urgencia digital menor que alternativas encaje claro. | AE11: Disponible | AF11: 7 | AG11: 7 | AH11: 7 | AI11: 7 | AJ11: 7 | AK11: Rehacer escala C2·terceros/plataforma (~7). Solo fichas; sin web/carta propia. | AL11: =IF(OR(A11="",COUNT(AF11:AJ11)<5),"",ROUND(SUMPRODUCT(AF11:AJ11,Guia!$B$7:$F$7),1)) -> 7 | AO11: Sí | AP11: No | AQ11: No | AR11: No | AS11: No | AT11: No | AU11: No
A12: indh006 | B12: indautxu-hosteleria-001 | C12: lote-002 | D12: Cork | E12: Bar | F12: Licenciado Poza, 45 | G12: Bilbao | H12: Dentro | I12: Activa con evidencia | J12: Alta | K12: Propia | L12: https://corkbilbao.com/ | M12: No localizado | N12: No localizado | O12: No localizado | P12: No aplica | Q12: No localizado | R12: No localizado | S12: No aplica | T12: Sin información | U12: Web propia corkbilbao.com | V12: Wine bar referencia; contacto profesional en web. | W12: Sin carta ni reserva digital en web propia. | X12: Carta vinos/pintxos online (rol 4: canal QR/Instagram). | Y12: Posible | Z12: https://corkbilbao.com/ | https://culinarybackstreets.com/stories/bilbao/cork-a-bilbao-bar-for-wine-and-basque-cooking | AA12: 46292 | AB12: expedientes/0006_Cork | AC12: Pendiente | AE12: Disponible | AF12: 5 | AG12: 5 | AH12: 7 | AI12: 7 | AJ12: 8 | AK12: Identidad clara; web breve sin carta; buen contacto publicado. | AL12: =IF(OR(A12="",COUNT(AF12:AJ12)<5),"",ROUND(SUMPRODUCT(AF12:AJ12,Guia!$B$7:$F$7),1)) -> 6 | AO12: Sí | AP12: No | AQ12: No | AR12: No | AS12: No | AT12: No | AU12: No
A13: indh007 | B13: indautxu-hosteleria-001 | C13: lote-002 | D13: El Puertito Oyster Bar | E13: Bar | F13: García Rivero Maisuaren Kalea, 9 | G13: Bilbao | H13: Dentro | I13: Activa con evidencia | J13: Alta | K13: Propia | L13: https://www.elpuertito.es/ | M13: No localizado | N13: No localizado | O13: No localizado | P13: No aplica | Q13: No localizado | R13: Sí | S13: No aplica | T13: Sin información | U13: elpuertito.es; catering eventos en web | V13: Marca ostras clara; sede Bilbao en web corporativa. | W13: Sin precios ni reserva online en canal propio. | X13: Landing reserva/disponibilidad Bilbao (rol 4: mix reserva/walk-in). | Y13: Posible | Z13: https://www.elpuertito.es/ | https://verybilbao.com/comercios/el-puertito/ | AA13: 46292 | AB13: expedientes/0007_Puertito | AC13: Pendiente | AE13: Disponible | AF13: 5 | AG13: 5 | AH13: 7 | AI13: 6 | AJ13: 7 | AK13: Buena identidad de marca; fricción carta/reserva; contacto web claro. | AL13: =IF(OR(A13="",COUNT(AF13:AJ13)<5),"",ROUND(SUMPRODUCT(AF13:AJ13,Guia!$B$7:$F$7),1)) -> 5.7 | AO13: Sí | AP13: No | AQ13: No | AR13: No | AS13: No | AT13: No | AU13: No
A14: indh008 | B14: indautxu-hosteleria-001 | C14: lote-002 | D14: Bar Joserra | E14: Bar | F14: Particular de Indautxu, 4 | G14: Bilbao | H14: Dentro | I14: Activa con evidencia | J14: Alta | K14: Plataforma | L14: https://bar-joserra.eatbu.com/?lang=es | M14: No confirmado | N14: No aplica | O14: No localizado | P14: No aplica | Q14: No localizado | R14: No localizado | S14: No aplica | T14: Sí | U14: Eatbu; Instagram @barjoserra_indautxu (citado) | V14: Bar clásico Indautxu; contacto en Eatbu; terraza declarada. | W14: Sin web propia ni carta con precios online. | X14: Web mínima propia + carta (rol 4: homónimos Casco Viejo). | Y14: Claro | Z14: https://bar-joserra.eatbu.com/?lang=es | https://bizkaikotortillakopa.eus/joserra-bar_2025/ | AA14: 46293 | AB14: expedientes/0008_Joserra | AC14: Seleccionado | AD14: Mejor nota (6,8); encaje claro; web propia + carta vs Eatbu. | AE14: En curso | AF14: 7 | AG14: 7 | AH14: 7 | AI14: 8 | AJ14: 8 | AK14: Rehacer escala C2·plataforma Eatbu (~7). Sin carta propia fiable. | AL14: =IF(OR(A14="",COUNT(AF14:AJ14)<5),"",ROUND(SUMPRODUCT(AF14:AJ14,Guia!$B$7:$F$7),1)) -> 7.3 | AM14: 7 | AN14: Post demo/comercial: web propia suma SEO, homónimos y carta/horario vs Eatbu; demos A/B e infografía v3 validadas. Techo por Eatbu existente, sin reserva en v1, conversión incierta. seguir_7_mensajero. | AO14: Sí | AP14: Sí | AQ14: Sí | AR14: Sí | AS14: Sí | AT14: Sí | AU14: No
A15: indh009 | B15: indautxu-hosteleria-001 | C15: lote-002 | D15: Ramen Shifu Indautxu | E15: Restaurante | F15: Alameda Urquijo, 44 | G15: Bilbao | H15: Dentro | I15: Activa con evidencia | J15: Alta | K15: Propia | L15: https://www.ramenshifu.com/ramen-shifu-indautxu/ | M15: Sí | N15: No localizado | O15: No localizado | P15: No aplica | Q15: No localizado | R15: No localizado | S15: No localizado | T15: Sin información | U15: ramenshifu.com carta; reservas tel. en /reservas | V15: Carta online completa con precios; horarios publicados. | W15: Reserva Indautxu solo telefónica; cadena centralizada. | X15: - | Y15: No evidente | Z15: https://www.ramenshifu.com/ramen-shifu-indautxu/ | https://www.ramenshifu.com/reservas/ | AA15: 46292 | AB15: expedientes/0009_RamenShifu | AC15: Pendiente | AE15: Disponible | AF15: 4 | AG15: 4 | AH15: 8 | AI15: 5 | AJ15: 6 | AK15: Alta cobertura digital de cadena; poco margen incremental local. | AL15: =IF(OR(A15="",COUNT(AF15:AJ15)<5),"",ROUND(SUMPRODUCT(AF15:AJ15,Guia!$B$7:$F$7),1)) -> 5 | AO15: Sí | AP15: No | AQ15: No | AR15: No | AS15: No | AT15: No | AU15: No
A16: indh010 | B16: indautxu-hosteleria-001 | C16: lote-002 | D16: Mugi | E16: Bar | F16: Licenciado Poza, 55 | G16: Bilbao | H16: Dentro | I16: Activa con evidencia | J16: Media | K16: Dominio inactivo | M16: No localizado | N16: No confirmado | O16: No localizado | P16: No aplica | Q16: No localizado | R16: No localizado | S16: No aplica | T16: Sí | U16: barmugi.com secuestrado; Instagram @el_mugi_bilbao; Jantour | V16: Solera Pozas documentada; teléfono coherente en guías. | W16: Dominio histórico inactivo; sin carta fiable online. | X16: Recuperar web + carta mínima (rol 4: dominio barmugi.com). | Y16: Claro | Z16: https://www.barmugi.com/ | https://jantour.elcorreo.com/restaurante/mugi.html | AA16: 46293 | AB16: expedientes/0010_Mugi | AC16: Seleccionado | AD16: Dominio barmugi.com inactivo/spam; web mínima en espera tras activo. | AE16: Disponible | AF16: 7 | AG16: 8 | AH16: 7 | AI16: 8 | AJ16: 7 | AK16: Rehacer escala C1·sin web (~7,5). Dominio inactivo; descubrimiento vía terceros. | AL16: =IF(OR(A16="",COUNT(AF16:AJ16)<5),"",ROUND(SUMPRODUCT(AF16:AJ16,Guia!$B$7:$F$7),1)) -> 7.5 | AO16: Sí | AP16: No | AQ16: No | AR16: No | AS16: No | AT16: No | AU16: No
A17: indh011 | B17: indautxu-hosteleria-001 | C17: lote-003 | D17: Bar Alameda | E17: Bar | F17: Alameda Urquijo, 40 | G17: Bilbao | H17: Dentro | I17: Activa con evidencia | J17: Alta | K17: Dominio inactivo | M17: No localizado | N17: No aplica | O17: No localizado | P17: No aplica | Q17: No localizado | R17: No localizado | S17: No aplica | T17: Sin información | U17: baralameda.es (inaccesible sesión); Bilbao Turismo; BAO | V17: Clásico bilbaíno; dirección y teléfono coherentes en guías. | W17: baralameda.es no resuelve DNS (barrido 2026-09-28); no es web obsoleta visible — hueco C1. | X17: Restaurar web mínima + carta estrella (rol 4: dominio baralameda.es). | Y17: Posible | Z17: https://www.baobilbao.com/bar-alameda-felipadas-y-platos-tradicionales/ | https://www.bilbaoturismo.net/BilbaoTurismo/es/buscador-de-pintxos/alameda | AA17: 46293 | AB17: expedientes/0011_Alameda | AC17: Pendiente | AE17: Disponible | AF17: 7 | AG17: 8 | AH17: 7 | AI17: 8 | AJ17: 7 | AK17: Barrido propias: dominio inactivo; casuística C1 (~7,5 orientativo). | AL17: =IF(OR(A17="",COUNT(AF17:AJ17)<5),"",ROUND(SUMPRODUCT(AF17:AJ17,Guia!$B$7:$F$7),1)) -> 7.5 | AO17: Sí | AP17: No | AQ17: No | AR17: No | AS17: No | AT17: No | AU17: No
A18: indh012 | B18: indautxu-hosteleria-001 | C18: lote-003 | D18: Ondori Indautxu | E18: Bar | F18: Particular de Indautxu | G18: Bilbao | H18: Dentro | I18: Activa con evidencia | J18: Media | K18: Solo redes | M18: No localizado | N18: No localizado | O18: No aplica | P18: No aplica | Q18: No localizado | R18: No localizado | S18: No aplica | T18: Sin información | U18: Instagram @ondoribotxo; prensa El Correo/Deia | V18: Propuesta vasco-asiática diferenciada; cobertura prensa reciente. | W18: Sin web sede Indautxu; portal exacto no unificado. | X18: Microsite Indautxu + carta digital (rol 4: separar de Botxo Casco Viejo). | Y18: Claro | Z18: https://www.deia.eus/bilbao/2025/03/05/ondori-indautxu-jurgi-arejita-centro-bilbao-9356637.html | https://www.elcorreo.com/jantour/restaurantes/bocados-vasco-orientales-centro-villa-20250315193124-nt.html | AA18: 46293 | AB18: expedientes/0012_Ondori | AC18: Pendiente | AE18: Disponible | AF18: 7 | AG18: 8 | AH18: 7 | AI18: 8 | AJ18: 7 | AK18: Rehacer escala C1·sin web (~7,5). Solo redes; sin vitrina propia ni carta indexable. | AL18: =IF(OR(A18="",COUNT(AF18:AJ18)<5),"",ROUND(SUMPRODUCT(AF18:AJ18,Guia!$B$7:$F$7),1)) -> 7.5 | AO18: Sí | AP18: No | AQ18: No | AR18: No | AS18: No | AT18: No | AU18: No
A19: indh013 | B19: indautxu-hosteleria-001 | C19: lote-003 | D19: Bierstube by H. Thate | E19: Bar | F19: Licenciado Poza, 50 | G19: Bilbao | H19: Dentro | I19: Activa con evidencia | J19: Alta | K19: Solo redes | M19: No localizado | N19: No localizado | O19: No aplica | P19: No aplica | Q19: No localizado | R19: Sí | S19: No aplica | T19: Sí | U19: Jantour; Instagram @bierstube_bilbao | V19: Propuesta cervecera clara; teléfono 944673642; terraza en Pozas. | W19: Sin web propia; carta solo en prensa/redes. | X19: Landing Pozas carta/eventos (rol 4: coordinación marca Thate). | Y19: Posible | Z19: https://jantour.elcorreo.com/restaurante/bierstube-by-h-thate.html | https://www.deia.eus/bizkaia/vida-social/2025/02/07/hermanos-thate-bar-licenciado-poza-bilbao-9250026.html | AA19: 46293 | AB19: expedientes/0013_Bierstube | AC19: Pendiente | AE19: Disponible | AF19: 7 | AG19: 8 | AH19: 7 | AI19: 8 | AJ19: 7 | AK19: Rehacer escala C1·sin web (~7,5). Solo redes; sin web propia ni carta indexable. | AL19: =IF(OR(A19="",COUNT(AF19:AJ19)<5),"",ROUND(SUMPRODUCT(AF19:AJ19,Guia!$B$7:$F$7),1)) -> 7.5 | AO19: Sí | AP19: No | AQ19: No | AR19: No | AS19: No | AT19: No | AU19: No
A20: indh014 | B20: indautxu-hosteleria-001 | C20: lote-003 | D20: Bar Restaurante Al Lío | E20: Restaurante | F20: García Rivero, 9 | G20: Bilbao | H20: Dentro | I20: Activa con evidencia | J20: Alta | K20: Propia | L20: https://alliobilbao.com/ | M20: Sí | N20: No localizado | O20: No localizado | P20: No aplica | Q20: No localizado | R20: No localizado | S20: No aplica | T20: Sin información | U20: alliobilbao.com | V20: Web con precios y promos semanales; email hola@alliobilbao.com. | W20: Misma dirección que El Puertito; reserva no online. | X20: - | Y20: No evidente | Z20: https://alliobilbao.com/ | AA20: 46292 | AB20: expedientes/0014_AlLio | AC20: Pendiente | AE20: Disponible | AF20: 4 | AG20: 4 | AH20: 7 | AI20: 7 | AJ20: 7 | AK20: Carta online ya resuelta; margen incremental bajo. | AL20: =IF(OR(A20="",COUNT(AF20:AJ20)<5),"",ROUND(SUMPRODUCT(AF20:AJ20,Guia!$B$7:$F$7),1)) -> 5.4 | AO20: Sí | AP20: No | AQ20: No | AR20: No | AS20: No | AT20: No | AU20: No
A21: indh015 | B21: indautxu-hosteleria-001 | C21: lote-003 | D21: Gangnam Korean BBQ Bilbao | E21: Restaurante | F21: Alameda San Mamés, 43 | G21: Bilbao | H21: Dentro | I21: Activa con evidencia | J21: Alta | K21: Solo redes | M21: Sí | N21: No localizado | O21: No localizado | P21: No aplica | Q21: No localizado | R21: No localizado | S21: No aplica | T21: No | U21: Instagram @gangnam_indautxu; tablet en sala (Deia) | V21: Experiencia digital en mesa; turnos y reserva teléfono documentados. | W21: Sin web pública ni reserva online. | X21: - | Y21: No evidente | Z21: https://www.deia.eus/gastronomia/2025/02/08/sabrosa-experiencia-bufe-barbacoa-coreana-9248114.html | https://www.instagram.com/gangnam_indautxu/ | AA21: 46292 | AB21: expedientes/0015_Gangnam | AC21: Pendiente | AE21: Disponible | AF21: 4 | AG21: 3 | AH21: 7 | AI21: 5 | AJ21: 6 | AK21: Operativa digital fuerte in situ; poco margen web externa. | AL21: =IF(OR(A21="",COUNT(AF21:AJ21)<5),"",ROUND(SUMPRODUCT(AF21:AJ21,Guia!$B$7:$F$7),1)) -> 4.6 | AO21: Sí | AP21: No | AQ21: No | AR21: No | AS21: No | AT21: No | AU21: No
A22: indh016 | B22: indautxu-hosteleria-001 | C22: lote-004 | D22: Guruzu | E22: Restaurante | F22: Manuel Allende, 10 | G22: Bilbao | H22: Dentro | I22: Activa con evidencia | J22: Alta | K22: Propia | L22: https://guruzu.eus/ | M22: Sí | N22: Sí | O22: No aplica | P22: No aplica | Q22: No confirmado | R22: Sí | S22: No aplica | T22: Sí | U22: guruzu.eus; /reserva/; menú del día online | V22: Web completa: menús, reserva, horarios, misión social. | W22: Varios teléfonos; tarjeta social poco detallada en web. | X22: Unificar reserva + FAQ tarjeta (rol 4: mix formulario/teléfono). | Y22: Posible | Z22: https://guruzu.eus/ | https://guruzu.eus/reserva/ | https://guruzu.eus/oferta-gastronomica/menu-del-dia/ | AA22: 46293 | AB22: expedientes/0016_Guruzu | AC22: Pendiente | AE22: Disponible | AF22: 4 | AG22: 4 | AH22: 8 | AI22: 6 | AJ22: 8 | AK22: Canal digital maduro; margen en reserva unificada y programa social. | AL22: =IF(OR(A22="",COUNT(AF22:AJ22)<5),"",ROUND(SUMPRODUCT(AF22:AJ22,Guia!$B$7:$F$7),1)) -> 5.4 | AO22: Sí | AP22: No | AQ22: No | AR22: No | AS22: No | AT22: No | AU22: No
A23: indh017 | B23: indautxu-hosteleria-001 | C23: lote-004 | D23: Larragán Berria | E23: Restaurante | F23: García Rivero, 10 | G23: Bilbao | H23: Dentro | I23: Activa con evidencia | J23: Media | K23: Solo terceros | M23: No localizado | N23: No localizado | O23: No aplica | P23: No aplica | Q23: No localizado | R23: No localizado | S23: No aplica | T23: Sin información | U23: El Correo sep/2026; Disfruta Bizkaia (histórico); tel. 944415069 no verificado | V23: Marca histórica; reapertura documentada en prensa reciente. | W23: Sin web propia; fichas online desactualizadas mezclan etapas. | X23: Landing Larragán Berria + SEO García Rivero (rol 4: carta Galicia vs clásicos). | Y23: Claro | Z23: https://www.elcorreo.com/bizkaia/historico-restaurante-larragan-regresa-impulsar-hosteleria-indautxu-20260923010312-nt.html | https://www.disfrutabizkaia.com/establecimiento/larragan-cafeteria/ | AA23: 46293 | AB23: expedientes/0017_LarraganBerria | AC23: Pendiente | AE23: Disponible | AF23: 7 | AG23: 7 | AH23: 7 | AI23: 7 | AJ23: 7 | AK23: Rehacer escala C2·terceros (~7). Fichas antiguas; sin web propia. | AL23: =IF(OR(A23="",COUNT(AF23:AJ23)<5),"",ROUND(SUMPRODUCT(AF23:AJ23,Guia!$B$7:$F$7),1)) -> 7 | AO23: Sí | AP23: No | AQ23: No | AR23: No | AS23: No | AT23: No | AU23: No
A24: indh018 | B24: indautxu-hosteleria-001 | C24: lote-004 | D24: Bølge Café | E24: Cafetería | F24: Licenciado Poza, 14 | G24: Bilbao | H24: Dentro | I24: Activa con evidencia | J24: Alta | K24: Propia | L24: https://www.bolgecafe.com/ | M24: No localizado | N24: No aplica | O24: No localizado | P24: No localizado | Q24: No localizado | R24: No localizado | S24: No aplica | T24: Sin información | U24: bolgecafe.com; Disfruta Bizkaia (605389074) | V24: Marca specialty y horarios claros en web. | W24: Sin precios/carta online pese a web cuidada. | X24: Carta digital en dominio existente (rol 4: pedido WhatsApp). | Y24: Posible | Z24: https://www.bolgecafe.com/ | https://www.disfrutabizkaia.com/establecimiento/bolge-cafe/ | AA24: 46293 | AB24: expedientes/0018_Bolge | AC24: Pendiente | AE24: Disponible | AF24: 4 | AG24: 3 | AH24: 7 | AI24: 8 | AJ24: 8 | AK24: Web sólida; salto a carta online es incremental. | AL24: =IF(OR(A24="",COUNT(AF24:AJ24)<5),"",ROUND(SUMPRODUCT(AF24:AJ24,Guia!$B$7:$F$7),1)) -> 5.4 | AO24: Sí | AP24: No | AQ24: No | AR24: No | AS24: No | AT24: No | AU24: No
A25: indh019 | B25: indautxu-hosteleria-001 | C25: lote-004 | D25: Ziripot | E25: Bar | F25: Licenciado Poza, 46 | G25: Bilbao | H25: Dentro | I25: Activa con evidencia | J25: Alta | K25: Propia | L25: https://www.ziripot.es/ | M25: No localizado | N25: No aplica | O25: No localizado | P25: No aplica | Q25: No localizado | R25: No localizado | S25: No aplica | T25: Sí | U25: ziripot.es (historia, horarios, terraza) | V25: Web con identidad, terraza y horarios amplios. | W25: Web propia estática/envejecida (Twitter legacy); sin carta ni teléfono; vitrina barra no digitalizada. | X25: Rediseño responsive + carta barra/terraza + teléfono/WhatsApp (rol 4: esquina Poza/Areilza). | Y25: Posible | Z25: https://www.ziripot.es/ | AA25: 46293 | AB25: expedientes/0019_Ziripot | AC25: Pendiente | AE25: Disponible | AF25: 8 | AG25: 7 | AH25: 7 | AI25: 7 | AJ25: 6 | AK25: Rehacer visual 2026-09-28: F envejecida (no IONOS); alta necesidad vs web útil previa subvalorada. | AL25: =IF(OR(A25="",COUNT(AF25:AJ25)<5),"",ROUND(SUMPRODUCT(AF25:AJ25,Guia!$B$7:$F$7),1)) -> 7.2 | AO25: Sí | AP25: No | AQ25: No | AR25: No | AS25: No | AT25: No | AU25: No
A26: indh020 | B26: indautxu-hosteleria-001 | C26: lote-004 | D26: Martxobi (MARTXO bi) | E26: Restaurante | F26: Alameda Urquijo, 48 | G26: Bilbao | H26: Dentro | I26: Activa con evidencia | J26: Alta | K26: Propia | L26: https://www.martxo.com/ | M26: Sí | N26: No localizado | O26: No aplica | P26: No aplica | Q26: No localizado | R26: Sí | S26: No aplica | T26: Sin información | U26: martxo.com; /carta-1; landing Martxo bi; tel. 613621018 | V26: Carta con precios online; segunda sede identificada. | W26: Contacto/reserva web centrada en sede Rodríguez Arias. | X26: Contacto bifurcado BGC vs Indautxu (rol 4: reservas sede). | Y26: Posible | Z26: https://www.martxo.com/carta-1 | https://www.deia.eus/bilbao/2026/07/15/restaurante-martxo-bilbao-amplia-presencia-apertura-11331702.html | AA26: 46293 | AB26: expedientes/0020_Martxobi | AC26: Pendiente | AE26: Disponible | AF26: 5 | AG26: 4 | AH26: 7 | AI26: 7 | AJ26: 7 | AK26: Carta digital fuerte; fricción en reserva multi-sede. | AL26: =IF(OR(A26="",COUNT(AF26:AJ26)<5),"",ROUND(SUMPRODUCT(AF26:AJ26,Guia!$B$7:$F$7),1)) -> 5.6 | AO26: Sí | AP26: No | AQ26: No | AR26: No | AS26: No | AT26: No | AU26: No
A27: indh021 | B27: indautxu-hosteleria-001 | C27: lote-005 | D27: El Huevo Frito | E27: Bar | F27: García Rivero, 1 | G27: Bilbao | H27: Dentro | I27: Activa con evidencia | J27: Alta | K27: Propia | L27: https://www.elhuevofrito.com/ | M27: Sí | N27: No aplica | O27: No confirmado | P27: No aplica | Q27: No localizado | R27: No localizado | S27: No aplica | T27: Sí | U27: elhuevofrito.com; Salir.com (944412249, info@elhuevofrito.com) | V27: Web propia moderna y breve: carta online, localización/mapa y contacto; take away declarado. | W27: Margen incremental bajo frente a vitrina ya resuelta; no encaja en hueco C. | X27: — | Y27: No evidente | Z27: http://www.elhuevofrito.com/ | https://www.salir.com/el-huevo-frito-bilbao-neg-2024.html | AA27: 46293 | AB27: expedientes/0021_HuevoFrito | AC27: Pendiente | AE27: Disponible | AF27: 3 | AG27: 3 | AH27: 8 | AI27: 7 | AJ27: 8 | AK27: Rehacer escala: casuística A (vitrina moderna completa; poco texto OK). N/V 2–3. | AL27: =IF(OR(A27="",COUNT(AF27:AJ27)<5),"",ROUND(SUMPRODUCT(AF27:AJ27,Guia!$B$7:$F$7),1)) -> 5.1 | AO27: Sí | AP27: No | AQ27: No | AR27: No | AS27: No | AT27: No | AU27: No
A28: indh022 | B28: indautxu-hosteleria-001 | C28: lote-005 | D28: Bar Txistua | E28: Bar | F28: García Rivero, 4 | G28: Bilbao | H28: Dentro | I28: Activa con evidencia | J28: Media | K28: Solo terceros | M28: No localizado | N28: No confirmado | O28: No localizado | P28: No aplica | Q28: No localizado | R28: No localizado | S28: No aplica | T28: Sí | U28: Citiservi 944420837; Pidemesa 617064107 | V28: Ubicación clara en García Rivero; perfil bar/café. | W28: Sin web; horarios contradictorios en agregadores. | X28: Landing horario/teléfono (rol 4: café vs barra). | Y28: Claro | Z28: https://www.citiservi.es/vizcaya/txistua-bilbao__2732449_464.html | https://pidemesa.es/restaurantes/bizkaia/bilbao/bar-txistua | AA28: 46293 | AB28: expedientes/0022_Txistua | AC28: Seleccionado | AD28: Brief etapa 2 completado; mayor nota cola 6,8; sin web propia. | AE28: En curso | AF28: 7 | AG28: 8 | AH28: 7 | AI28: 8 | AJ28: 7 | AK28: Rehacer escala C1·sin web (~7,5). Sin dominio; datos en agregadores contradictorios. | AL28: =IF(OR(A28="",COUNT(AF28:AJ28)<5),"",ROUND(SUMPRODUCT(AF28:AJ28,Guia!$B$7:$F$7),1)) -> 7.5 | AO28: Sí | AP28: Sí | AQ28: Sí | AR28: Sí | AS28: No | AT28: No | AU28: No
A29: indh023 | B29: indautxu-hosteleria-001 | C29: lote-005 | D29: Bar Okela | E29: Bar | F29: García Rivero, 8 | G29: Bilbao | H29: Dentro | I29: Activa con evidencia | J29: Alta | K29: Propia | L29: https://www.okelabilbao.com/ | M29: No localizado | N29: No localizado | O29: No confirmado | P29: No localizado | Q29: No localizado | R29: No confirmado | S29: No aplica | T29: Sí | U29: okelabilbao.com; barokela.com (citado, no verificado); Disfruta Bizkaia | V29: Marca desde 1983; web con horario y teléfono; referencias venta online pionera. | W29: Dominios/teléfonos dispersos; shop no accesible en sesión. | X29: Hub único marca+pedidos (rol 4: mix barra/e-commerce). | Y29: Posible | Z29: https://www.okelabilbao.com/ | https://www.disfrutabizkaia.com/establecimiento/okela-bar/ | AA29: 46293 | AB29: expedientes/0023_Okela | AC29: Pendiente | AE29: Disponible | AF29: 5 | AG29: 4 | AH29: 8 | AI29: 6 | AJ29: 8 | AK29: Canal digital avanzado; mejora incremental menor. | AL29: =IF(OR(A29="",COUNT(AF29:AJ29)<5),"",ROUND(SUMPRODUCT(AF29:AJ29,Guia!$B$7:$F$7),1)) -> 5.7 | AO29: Sí | AP29: No | AQ29: No | AR29: No | AS29: No | AT29: No | AU29: No
A30: indh024 | B30: indautxu-hosteleria-001 | C30: lote-005 | D30: Zaka Restaurante | E30: Restaurante | F30: Simón Bolívar, 11 | G30: Bilbao | H30: Dentro | I30: Activa con evidencia | J30: Alta | K30: Propia | L30: https://zakarestaurante.com/ | M30: No localizado | N30: No confirmado | O30: No localizado | P30: No aplica | Q30: No localizado | R30: No localizado | S30: No aplica | T30: Sí | U30: zakarestaurante.com; Deia; tel. 944014561 | V30: Horarios amplios en web; propuesta gastrobar clara. | W30: Sin carta/menú con precios online. | X30: Menú día y carta noche en web (rol 4: reserva tel vs plataforma). | Y30: Posible | Z30: https://zakarestaurante.com/ | https://www.deia.eus/gastronomia/2022/05/06/zaka-bar-restaurante-caracter-polivante-1704809.html | AA30: 46293 | AB30: expedientes/0024_Zaka | AC30: Pendiente | AE30: Disponible | AF30: 6 | AG30: 5 | AH30: 7 | AI30: 6 | AJ30: 8 | AK30: Web con huecos carta/reserva; operación madura. | AL30: =IF(OR(A30="",COUNT(AF30:AJ30)<5),"",ROUND(SUMPRODUCT(AF30:AJ30,Guia!$B$7:$F$7),1)) -> 6.1 | AO30: Sí | AP30: No | AQ30: No | AR30: No | AS30: No | AT30: No | AU30: No
A31: indh025 | B31: indautxu-hosteleria-001 | C31: lote-005 | D31: Bar Particular | E31: Bar | F31: Indautxu Kalea, 9 | G31: Bilbao | H31: Dentro | I31: Activa con evidencia | J31: Media | K31: Solo terceros | M31: No localizado | N31: No aplica | O31: No localizado | P31: No aplica | Q31: No localizado | R31: No localizado | S31: No aplica | T31: Sí | U31: TodoBares (reseñas); Google citado en agregador | V31: Pinchos y terraza muy valorados en reseñas. | W31: Sin web ni teléfono claro en fuentes consultadas. | X31: Micrositio horario/especialidades (rol 4: terraza walk-in vs reserva). | Y31: Claro | Z31: https://www.todobares.com/bar/bar-particular-bilbao/ | AA31: 46293 | AB31: expedientes/0025_Particular | AC31: Pendiente | AE31: Disponible | AF31: 7 | AG31: 7 | AH31: 7 | AI31: 7 | AJ31: 7 | AK31: Rehacer escala C2·terceros (~7). Solo agregadores; sin canal propio. | AL31: =IF(OR(A31="",COUNT(AF31:AJ31)<5),"",ROUND(SUMPRODUCT(AF31:AJ31,Guia!$B$7:$F$7),1)) -> 7 | AO31: Sí | AP31: No | AQ31: No | AR31: No | AS31: No | AT31: No | AU31: No
A32: indh026 | B32: indautxu-hosteleria-001 | C32: lote-006 | D32: Bilb8 | E32: Bar | F32: García Rivero, 7 | G32: Bilbao | H32: Dentro | I32: Activa con evidencia | J32: Media | K32: Solo redes | M32: No localizado | N32: No localizado | O32: No localizado | P32: No aplica | Q32: No localizado | R32: No localizado | S32: No aplica | T32: Sí | U32: Instagram @bilbootxo; bilb8carta.com (404 sesión); Bilbao Centro 944972661 bilbotxo2024@gmail.com | V32: Cazuelitas y pica-pica con cobertura prensa 2024; terraza descrita. | W32: Carta web caída; mismo portal que Indusi (indh001). | X32: Micrositio carta/horario diferenciado Indusi (rol 4: accesos nº7). | Y32: Posible | Z32: https://www.elcorreo.com/jantour/restaurantes/cazuelitas-recetario-tradicional-alegran-botxo-20241005012607-nt.html | https://www.bilbaocentro.com/es/comercios/bilb_8 | AA32: 46293 | AB32: expedientes/0026_Bilb8 | AC32: Pendiente | AE32: Disponible | AF32: 7 | AG32: 8 | AH32: 7 | AI32: 8 | AJ32: 7 | AK32: Rehacer escala C1·sin web (~7,5). Carta caída; vitrina inestable (portal compartido). | AL32: =IF(OR(A32="",COUNT(AF32:AJ32)<5),"",ROUND(SUMPRODUCT(AF32:AJ32,Guia!$B$7:$F$7),1)) -> 7.5 | AO32: Sí | AP32: No | AQ32: No | AR32: No | AS32: No | AT32: No | AU32: No
A33: indh027 | B33: indautxu-hosteleria-001 | C33: lote-006 | D33: Café Originale | E33: Cafetería | F33: Ercilla, 19 | G33: Bilbao | H33: Dentro | I33: Activa con evidencia | J33: Alta | K33: Propia | L33: https://cafeoriginale.com/ | M33: Sí | N33: No localizado | O33: No aplica | P33: No localizado | Q33: No localizado | R33: No localizado | S33: No aplica | T33: Sin información | U33: cafeoriginale.com/menu (imágenes); tel. 623356978 | V33: Specialty coffee + brunch; web y menú online cuidados. | W33: Carta en JPG; sin reserva formal. | X33: Carta HTML accesible + señal espera fines de semana (rol 4). | Y33: Posible | Z33: https://cafeoriginale.com/ | https://cafeoriginale.com/menu/ | AA33: 46293 | AB33: expedientes/0027_Originale | AC33: Pendiente | AE33: Disponible | AF33: 4 | AG33: 3 | AH33: 8 | AI33: 6 | AJ33: 7 | AK33: Web propia madura; mejoras incrementales carta/reserva. | AL33: =IF(OR(A33="",COUNT(AF33:AJ33)<5),"",ROUND(SUMPRODUCT(AF33:AJ33,Guia!$B$7:$F$7),1)) -> 5 | AO33: Sí | AP33: No | AQ33: No | AR33: No | AS33: No | AT33: No | AU33: No
A34: indh028 | B34: indautxu-hosteleria-001 | C34: lote-006 | D34: Restaurante Olagarro (Rodríguez Arias) | E34: Restaurante | F34: Rodríguez Arias, 64 | G34: Bilbao | H34: Dentro | I34: Activa con evidencia | J34: Alta | K34: Propia | L34: https://restauranteolagarro.com/ | M34: No localizado | N34: No confirmado | O34: No localizado | P34: No aplica | Q34: No localizado | R34: No confirmado | S34: No aplica | T34: Sí | U34: restauranteolagarro.com; Bilbao Dendak; tel. 944393215 | V34: Referente pulpo/gallego; desayunos y barra pintxos; web multi-sede. | W34: Precios/carta poco visibles online; reserva telefónica. | X34: Landing sede 64 con menú/barra (rol 4: TheFork?). | Y34: Posible | Z34: https://restauranteolagarro.com/ | https://www.bilbaodendak.eus/comercios/olagarro/ | AA34: 46293 | AB34: expedientes/0028_Olagarro | AC34: Pendiente | AE34: Disponible | AF34: 5 | AG34: 4 | AH34: 8 | AI34: 5 | AJ34: 8 | AK34: Web propia con huecos transaccionales; cadena con varias sedes. | AL34: =IF(OR(A34="",COUNT(AF34:AJ34)<5),"",ROUND(SUMPRODUCT(AF34:AJ34,Guia!$B$7:$F$7),1)) -> 5.5 | AO34: Sí | AP34: No | AQ34: No | AR34: No | AS34: No | AT34: No | AU34: No
A35: indh029 | B35: indautxu-hosteleria-001 | C35: lote-006 | D35: The Wicklow Arms | E35: Bar | F35: Rodríguez Arias, 30 | G35: Bilbao | H35: Dentro | I35: Activa con evidencia | J35: Alta | K35: Solo redes | L35: https://www.facebook.com/pages/Wicklow-Arms/123987794330023 | M35: No localizado | N35: No confirmado | O35: No confirmado | P35: No aplica | Q35: No localizado | R35: No localizado | S35: No aplica | T35: Sí | U35: Facebook; Schlouk Map; tel. 944425148 | V35: Pub irlandés icónico; reputación Guinness; horarios amplios. | W35: Sin web propia; reservas inconsistentes en agregadores. | X35: Landing horario/reservas grupos (rol 4: mix local/turismo). | Y35: Posible | Z35: https://www.schlouk-map.com/es/places/the-wicklow-arms | https://destaco.es/empresa/the-wicklow-arms-bilbao | AA35: 46293 | AB35: expedientes/0029_Wicklow | AC35: Pendiente | AE35: Disponible | AF35: 6 | AG35: 5 | AH35: 6 | AI35: 7 | AJ35: 7 | AK35: Marca fuerte; vitrina digital limitada a Facebook. | AL35: =IF(OR(A35="",COUNT(AF35:AJ35)<5),"",ROUND(SUMPRODUCT(AF35:AJ35,Guia!$B$7:$F$7),1)) -> 6 | AO35: Sí | AP35: No | AQ35: No | AR35: No | AS35: No | AT35: No | AU35: No
A36: indh030 | B36: indautxu-hosteleria-001 | C36: lote-006 | D36: Bar Gure | E36: Bar | F36: Ercilla, 26 | G36: Bilbao | H36: Dentro | I36: Activa con evidencia | J36: Media | K36: Solo terceros | M36: No localizado | N36: No aplica | O36: No localizado | P36: No aplica | Q36: No localizado | R36: No localizado | S36: No aplica | T36: Sin información | U36: Citiservi; Sluurpy; InTravel; tel. 944150145 | V36: Teléfono y dirección estables; barra matinal documentada en terceros. | W36: Sin web; horarios dispares sáb/dom y cierre; enlace Guria erróneo en agregadores. | X36: Landing horario/desayuno (rol 4: sábados abierto?). | Y36: Claro | Z36: https://www.citiservi.es/vizcaya/bar-gure-bilbao__2732443_464.html | https://www.sluurpy.es/bilbao/restaurant/1843857/gure-bar | https://intravel.net/bilbao/nightlife/bar-gure | AA36: 46293 | AB36: expedientes/0030_Gure | AC36: Seleccionado | AD36: Brief etapa 2 completado; mayor nota cola 6,8; sin web propia en Ercilla. | AE36: En curso | AF36: 7 | AG36: 7 | AH36: 6 | AI36: 8 | AJ36: 6 | AK36: Más fuentes etapa 2; horario aún conflictivo; sin carta ni redes. | AL36: =IF(OR(A36="",COUNT(AF36:AJ36)<5),"",ROUND(SUMPRODUCT(AF36:AJ36,Guia!$B$7:$F$7),1)) -> 7 | AO36: Sí | AP36: Sí | AQ36: Sí | AR36: Sí | AS36: No | AT36: No | AU36: No
A37: indh031 | B37: indautxu-hosteleria-001 | C37: lote-007 | D37: Marakay | E37: Bar | F37: Rodríguez Arias, 26 | G37: Bilbao | H37: Dentro | I37: Activa con evidencia | J37: Media | K37: Dominio inactivo | M37: No localizado | N37: No aplica | O37: No localizado | P37: No aplica | Q37: No localizado | R37: No localizado | S37: No aplica | T37: Sí | U37: Bilbao Turismo; cafeteriasmarakay.es (500); cafeteriasmarakay@hotmail.es 944415066 | V37: Marca clásica jamón/bocaditos; contacto en turismo oficial. | W37: Web propia inoperativa; fichas con dirección/teléfonos discordantes. | X37: Landing mínima horario + especialidad (rol 4: búsqueda local). | Y37: Posible | Z37: https://www.bilbaoturismo.net/BilbaoTurismo/en/cafes--ice-cream-parlours-and-cake-shops/marakay | https://www.sluurpy.es/bilbao/restaurant/1836800/marakay | AA37: 46293 | AB37: expedientes/0031_Marakay | AC37: Pendiente | AE37: Disponible | AF37: 7 | AG37: 8 | AH37: 7 | AI37: 8 | AJ37: 7 | AK37: Rehacer escala C1·sin web (~7,5). Dominio inactivo; sin presencia propia fiable. | AL37: =IF(OR(A37="",COUNT(AF37:AJ37)<5),"",ROUND(SUMPRODUCT(AF37:AJ37,Guia!$B$7:$F$7),1)) -> 7.5 | AO37: Sí | AP37: No | AQ37: No | AR37: No | AS37: No | AT37: No | AU37: No
A38: indh032 | B38: indautxu-hosteleria-001 | C38: lote-007 | D38: Goizeko Izarra | E38: Restaurante | F38: Gregorio de la Revilla, 9 | G38: Bilbao | H38: Dentro | I38: Activa con evidencia | J38: Alta | K38: Propia | L38: https://goizekoizarra.es/ | M38: Sí | N38: No confirmado | O38: No localizado | P38: No aplica | Q38: No localizado | R38: No confirmado | S38: No aplica | T38: Sí | U38: goizekoizarra.es/carta; goizekoizarrarestaurante.com; restaurante@goizekoizarra.es | V38: Carta trilingüe con precios; propuesta txuletón/pintxos clara. | W38: Dos dominios/emails; reserva solo teléfono. | X38: Unificar web + reserva online (rol 4: llamadas). | Y38: Posible | Z38: https://goizekoizarra.es/ | https://goizekoizarra.es/carta-goizeko-izarra/ | AA38: 46293 | AB38: expedientes/0032_GoizekoIzarra | AC38: Pendiente | AE38: Disponible | AF38: 4 | AG38: 4 | AH38: 8 | AI38: 5 | AJ38: 8 | AK38: Carta online sólida; duplicidad webs reduce valor incremental. | AL38: =IF(OR(A38="",COUNT(AF38:AJ38)<5),"",ROUND(SUMPRODUCT(AF38:AJ38,Guia!$B$7:$F$7),1)) -> 5.2 | AO38: Sí | AP38: No | AQ38: No | AR38: No | AS38: No | AT38: No | AU38: No
A39: indh033 | B39: indautxu-hosteleria-001 | C39: lote-007 | D39: Restaurante Yandiola | E39: Restaurante | F39: Plaza Arriquíbar, 4 (Azkuna Zentroa) | G39: Bilbao | H39: Límite | I39: Activa con evidencia | J39: Alta | K39: Propia | L39: https://yandiola.com/ | M39: Sí | N39: Sí | O39: No aplica | P39: No aplica | Q39: No localizado | R39: Sí | S39: No aplica | T39: Sí | U39: yandiola.com/reservas; info@grupoyandiola.com; Guía Repsol | V39: Reserva web, carta estructurada, terraza icónica Azkuna. | W39: Acceso complejo en edificio; propuesta ya premium. | X39: - | Y39: No evidente | Z39: https://yandiola.com/ | https://yandiola.com/reservas/ | https://www.guiarepsol.com/es/fichas/restaurante/yandiola-9051/ | AA39: 46293 | AB39: expedientes/0033_Yandiola | AC39: Pendiente | AE39: Disponible | AF39: 3 | AG39: 3 | AH39: 9 | AI39: 5 | AJ39: 9 | AK39: Digitalización alta en límite Azkuna; poca necesidad demo genérica. | AL39: =IF(OR(A39="",COUNT(AF39:AJ39)<5),"",ROUND(SUMPRODUCT(AF39:AJ39,Guia!$B$7:$F$7),1)) -> 4.9 | AO39: Sí | AP39: No | AQ39: No | AR39: No | AS39: No | AT39: No | AU39: No
A40: indh034 | B40: indautxu-hosteleria-001 | C40: lote-007 | D40: Restaurante Zarate | E40: Restaurante | F40: Licenciado Poza, 65 | G40: Bilbao | H40: Dentro | I40: Activa con evidencia | J40: Alta | K40: Propia | L40: https://zarate.restaurant/ | M40: No confirmado | N40: No confirmado | O40: No aplica | P40: No aplica | Q40: No localizado | R40: No localizado | S40: No aplica | T40: Sin información | U40: zarate.restaurant (no fetch); Turismo Euskadi; restaurantezarate@gmail.com | V40: Marca Michelin y contacto oficial Turismo Euskadi. | W40: Web no verificada en sesión (protección bot). | X40: - | Y40: No evidente | Z40: https://turismo.euskadi.eus/es/restaurantes/restaurante-zarate/webtur00-content/es/ | AA40: 46293 | AB40: expedientes/0034_Zarate | AC40: Pendiente | AE40: Disponible | AF40: 4 | AG40: 4 | AH40: 7 | AI40: 6 | AJ40: 8 | AK40: Alto nivel asumido; auditoría web pendiente. | AL40: =IF(OR(A40="",COUNT(AF40:AJ40)<5),"",ROUND(SUMPRODUCT(AF40:AJ40,Guia!$B$7:$F$7),1)) -> 5.3 | AO40: Sí | AP40: No | AQ40: No | AR40: No | AS40: No | AT40: No | AU40: No
A41: indh035 | B41: indautxu-hosteleria-001 | C41: lote-007 | D41: Ados | E41: Bar | F41: Licenciado Poza, 48 | G41: Bilbao | H41: Dentro | I41: Activa con evidencia | J41: Alta | K41: Solo redes | L41: https://www.instagram.com/cocktails_bar_ados/ | M41: No localizado | N41: No aplica | O41: No localizado | P41: No aplica | Q41: No localizado | R41: No localizado | S41: No aplica | T41: Sí | U41: Instagram @cocktails_bar_ados; Facebook Ados; 946548847 | V41: Coctelería con presencia social y terraza citada. | W41: Sin web propia; carta/horario en redes. | X41: Landing cócteles + grupos (rol 4: DM Instagram). | Y41: Posible | Z41: https://intravel.net/es/bilbao/nightlife/ados | https://premiojovenempresario.es/ver/ados-bilbao | AA41: 46293 | AB41: expedientes/0035_Ados | AC41: Pendiente | AE41: Disponible | AF41: 6 | AG41: 5 | AH41: 6 | AI41: 7 | AJ41: 7 | AK41: Solo redes; oportunidad landing nocturna moderada. | AL41: =IF(OR(A41="",COUNT(AF41:AJ41)<5),"",ROUND(SUMPRODUCT(AF41:AJ41,Guia!$B$7:$F$7),1)) -> 6 | AO41: Sí | AP41: No | AQ41: No | AR41: No | AS41: No | AT41: No | AU41: No
A42: indh036 | B42: indautxu-hosteleria-001 | C42: lote-008 | D42: Garibolo | E42: Restaurante | F42: Fernández del Campo, 7 | G42: Bilbao | H42: Dentro | I42: Activa con evidencia | J42: Alta | K42: Propia | L42: https://www.garibolo.com/ | M42: No localizado | N42: No confirmado | O42: No localizado | P42: No aplica | Q42: No localizado | R42: No localizado | S42: No aplica | T42: Sin información | U42: garibolo.com; 944 223 255; Salir.com | V42: Marca veggie consolidada; web con horario y contacto. | W42: Sin carta/precios online; reserva solo teléfono. | X42: Carta semanal web + reserva (rol 4: grupos). | Y42: Posible | Z42: https://www.garibolo.com/ | https://www.salir.com/garibolo-bilbao-neg-126905.html | AA42: 46293 | AB42: expedientes/0036_Garibolo | AC42: Pendiente | AE42: Disponible | AF42: 4 | AG42: 4 | AH42: 7 | AI42: 6 | AJ42: 8 | AK42: Web propia; fricción carta/reserva; contacto claro. | AL42: =IF(OR(A42="",COUNT(AF42:AJ42)<5),"",ROUND(SUMPRODUCT(AF42:AJ42,Guia!$B$7:$F$7),1)) -> 5.3 | AO42: Sí | AP42: No | AQ42: No | AR42: No | AS42: No | AT42: No | AU42: No
...

Sheet Guia
A2: Uso y puntuación
A4: Pesos de puntuación
A6: Criterio | B6: Necesidad | C6: Valor añadido | D6: Información | E6: Mantenibilidad | F6: Contacto
A7: Peso | B7: 0.25 | C7: 0.3 | D7: 0.15 | E7: 0.2 | F7: 0.1
A9: Ancla | B9: Necesidad | C9: Valor añadido | D9: Información | E9: Mantenibilidad | F9: Contacto
A10: 1 | B10: Necesidades bien cubiertas | C10: Sin mejora diferencial | D10: Datos escasos o contradictorios | E10: Alta carga operativa o soporte | F10: Sin canal localizado
A11: 5 | B11: Fricción plausible parcial | C11: Mecanismo plausible por validar | D11: Identidad y oferta contrastadas | E11: Revisiones e integración acotables | F11: Canal profesional publicado
A12: 10 | B12: Problema relevante acreditado | C12: Mejora específica con evidencia | D12: Datos actuales para personalizar | E12: Entrega repetible y carga baja | F12: Canal y responsable acreditados
A15: Nota | B15: Media ponderada de cinco factores enteros 1–10, redondeada a un decimal. No es probabilidad de venta.
A16: Datos ausentes | B16: Si falta ID o un factor, la nota queda vacía. No sustituir desconocidos por ceros o un 5 neutro.
A17: Sí / No | B17: Sí = etapa completada y vigente. No = pendiente, bloqueada o por revisar; ver Estado operativo y motivo.
A18: Selección | B18: La casilla 2 indica evaluación terminada. Solo Decisión selección = Seleccionado permite continuar a 3.
A19: Servicios digitales | B19: Sí = observado. No confirmado = anunciado o no verificable. No localizado no demuestra inexistencia.
A20: Prioridad | B20: 2 elige pendientes por nota descendente. Empates: fecha más antigua, después ID. Conserva un activo pendiente.
A21: Nueva investigación | B21: 1 añade hasta cinco nuevos por lote. Consultar todos los IDs e identidades, también en otras campañas.
A22: Guardado | B22: Cerrar este libro antes de que Cursor escriba. No usar simultáneamente desde dos equipos.
A23: Historial | B23: No borrar filas ni reutilizar IDs. Cambios relevantes reabren únicamente etapas afectadas del mismo negocio.
A24: Fila nueva | B24: Usar la primera fila sin ID. Ampliar tabla, fórmula y validaciones cuando se agoten las 200 preparadas.
A25: Fuentes | B25: URLs en Fuentes URL y detalle de afirmaciones/versiones en el expediente. No hay negocios precargados.
A26: Límite de campaña | B26: 20 negocios inicialmente; 5 por ejecución. El registro conserva otras campañas y evita duplicados.
